Workbook

Sheet RFP_İNPUTS
A1: Requirement | B1: Value | C1: Unit | D1: Notes
A2: Payload | B2: 150 | C2: kg | D2: Fixed payload
A3: Landing stall speed | B3: 40 | C3: KCAS | D3: Landing configuration
A4: Clean stall speed | B4: 50 | C4: KCAS | D4: Clean configuration
A5: Service ceiling | B5: 24000 | C5: ft | D5: Minimum
A6: Cruise ceiling | B6: 18000 | C6: ft | D6: Minimum
A7: Cruise speed | B7: 70 | C7: KCAS | D7: RFP cruise speed
A8: Endurance | B8: 24 | C8: h | D8: At cruise altitude
A9: Operation radius | B9: 2000 | C9: km | D9: One-way radius
A10: Total mission cruise range | B10: 4000 | C10: km | D10: Outbound + inbound
A11: Max ROC at sea level | B11: 1200 | C11: fpm | D11: Minimum
A12: Takeoff distance | B12: 2000 | C12: m | D12: Optional, ISA +30

Sheet 02_Unit_Conversions
A1: Quantity | B1: From | C1: To | D1: Factor | E1: Notes | G1: Parameter | H1: Original Value | I1: Original Unit | J1: Converted Value | K1: Converted Unit
A2: Speed | B2: knot | C2: m/s | D2: 0.514444 | E2: multiply knot by this | G2: Landing stall speed | H2: 40 | I2: KCAS | J2: =H2*0.514444 -> 20.57776 | K2: m/s
A3: Speed | B3: knot | C3: ft/s | D3: 168781 | E3: multiply knot by this | G3: Clean stall speed | H3: 50 | I3: KCAS | J3: =H3*0.514444 -> 25.7222 | K3: m/s
A4: Distance | B4: km | C4: m | D4: 1000 | E4: multiply km by this | G4: Cruise speed | H4: 70 | I4: KCAS | J4: =H4*0.514444 -> 36.01108 | K4: m/s
A5: Distance | B5: km | C5: nautical mile | D5: 0.539957 | E5: multiply km by this | G5: Service ceiling | H5: 24000 | I5: ft | J5: =H5*0.3048 -> 7315.2 | K5: m
A6: Distance | B6: nautical mile | C6: km | D6: 1852 | E6: multiply nm by this | G6: Cruise ceiling | H6: 18000 | I6: ft | J6: =H6*0.3048 -> 5486.4 | K6: m
A7: Altitude | B7: ft | C7: m | D7: 0.3048 | E7: multiply ft by this | G7: Operation radius | H7: 2000 | I7: km | J7: =H7*1000 -> 2000000 | K7: m
A8: Altitude | B8: m | C8: ft | D8: 328084 | E8: multiply m by this | G8: Total mission cruise range | H8: 4000 | I8: km | J8: =H8*1000 -> 4000000 | K8: m
A9: ROC | B9: fpm | C9: m/s | D9: 0.00508 | E9: multiply fpm by this | G9: Max ROC at sea level | H9: 1200 | I9: fpm | J9: =H9*0.00508 -> 6.096 | K9: m/s
A10: Weight force | B10: kg | C10: N | D10: 980665 | E10: mass to weight force
A11: Power | B11: hp | C11: W | D11: 745.7 | E11: horsepower to watt
A12: Power | B12: kW | C12: hp | D12: 134102 | E12: kilowatt to hp

Sheet 03_Atmosphere
A1: Hesap | B1: İrtifa | D1: A | E1: B | F1: C
A2: Stall speed | B2: Sea level | D2: Constant | E2: Value | F2: Unit | H2: Altitude case | I2: h | J2: Unit | K2: h_m | L2: T | M2: P | N2: rho | O2: sigma
A3: Takeoff | B3: Sea level, ISA +30 | D3: Sea level temperature, T0 | E3: 288.15 | F3: K | H3: Sea Level | I3: 0 | J3: ft | K3: =I3*0.3048 -> 0 | L3: =$E$3-$E$6*I3 -> 288.15 | M3: =$E$4*(L3/$E$3)^($E$8/($E$7*$E$5)) -> 101325 | N3: =M3/($E$7*L3) -> 1.2250123 | O3: =N3/$E$5 -> 1.00001
A4: Cruise / endurance / radius | B4: 18,000 ft | D4: Sea level pressure, P0 | E4: 101325 | F4: Pa | H4: Cruise Ceiling | I4: 18000 | J4: ft | K4: =I4*0.3048 -> 5486.4 | L4: =$E$3-$E$6*K4 -> 252.4884 | M4: =$E$4*(L4/$E$3)^($E$8/($E$7*$E$6)) -> 50587.468 | N4: =M4/($E$7*L4) -> 0.69798158 | O4: =N4/$E$5 -> 0.56978088
A5: Service ceiling | B5: 24,000 ft | D5: Sea level density, rho0 | E5: 1.225 | F5: kg/m³ | H5: Service Ceiling | I5: 24000 | J5: ft | K5: =I5*0.3048 -> 7315.2 | L5: =$E$3-$E$6*K5 -> 240.6012 | M5: =$E$4*(L5/$E$3)^($E$8/($E$7*$E$6)) -> 39257.892 | N5: =M5/($E$7*L5) -> 0.568423 | O5: =N5/$E$5 -> 0.46401877
A6: Cruise ceiling | B6: 18,000 ft | D6: Temperature lapse rate, a | E6: 0.0065 | F6: K/m
D7: Gas constant, R | E7: 287.05 | F7: J/kgK
D8: Gravity, g | E8: 9.81 | F8: m/s²

Sheet 04_Competitor_Data
A1: Aircraft | B1: Manufacturer | C1: Country | D1: UAV Class | E1: Primary Mission | F1: Engine Type | G1: Engine Model | H1: Engine Power hp | I1: Propeller Type | J1: Wingspan m | K1: Wing Area m2 | L1: Aspect Ratio | M1: Fuselage Length m | N1: Height m | O1: Horizontal Tail Area m2 | P1: Vertical Tail Area m2 | Q1: MTOW kg | R1: Empty Weight kg | S1: Fuel Weight kg | T1: Payload kg | U1: Useful Load kg | V1: Max Speed kt | W1: Cruise Speed kt | X1: ROC SL fpm | Y1: Service Ceiling ft | Z1: Cruise Ceiling ft | AA1: Endurance h | AB1: Operational Radius km | AC1: Total Range km | AD1: Stall Landing KCAS | AE1: Stall Clean KCAS | AF1: Takeoff Distance m | AG1: Source 1 | AH1: Source 2 | AI1: Source 3 | AJ1: Confidence | AK1: Notes | AL1: Weight Sum Check kg | AM1: Weight Error kg | AN1: Weight Error % | AO1: Weight Status | AP1: Other / Missing Weight kg | AQ1: Weight Comment Fuel/payload/MTOW inconsistent; needs source correction. | AR1: Final Use Status | AS1: Correction Priority | AT1: Next Data Action
A2: Bayraktar TB2 | B2: Baykar Defence | C2: Türkiye | D2: MALE / Tactical UAV | E2: Armed reconnaissance | F2: Piston Engine | G2: Not specified in draft | H2: 100 | I2: Variable Pitch | J2: 12 | K2: 46060 | L2: 20 | M2: 46148 | N2: 46055 | O2: 46143 | P2: 49310 | Q2: 700 | R2: 550 | S2: 220 | T2: 150 | U2: 150 | V2: 110 | W2: 90 | X2: 800 | Y2: 25000 | Z2: 18000 | AA2: 24 | AC2: 3400 | AD2: 40-45 | AE2: 50-55 | AF2: 300 | AG2: Mak_473 draft report | AH2: Needs primary source | AI2: Needs cross-check | AJ2: Low | AK2: Weight breakdown inconsistent: We + Wf + Wp exceeds MTOW | AL2: =R2+S2+T2 -> 920 | AM2: =AL2-Q2 -> 220 | AN2: =AM2/Q2 -> 0.31428571 | AO2: =IF(ABS(AN2)<0.05,"OK","CHECK") -> CHECK | AP2: =Q2-R2-S2-T2 -> -220 | AQ2: Fuel weight likely not compatible with MTOW and payload simultaneously; source correction required. | AR2: =IF(AO2="OK","PROVISIONAL USE","SOURCE CORRECTION REQUIRED") -> SOURCE CORRECTION REQUIRED | AS2: =IF(ABS(AN2)<0.05,"LOW",IF(ABS(AN2)<0.15,"MEDIUM","HIGH")) -> HIGH | AT2: Do not use fuel-weight value before correction; MTOW, empty weight, fuel and payload are inconsistent.
A3: TUSAŞ ANKA-S | B3: Turkish Aerospace Industries | C3: Türkiye | D3: MALE UAV | E3: Medium-altitude reconnaissance | F3: Turboprop | G3: Not specified in draft | H3: 170 | I3: Variable Pitch | J3: 46159 | K3: 15.75 | L3: 19.44 | M3: 46181 | N3: 45717 | O3: 24167 | P3: 48245 | Q3: 1700 | R3: 900 | S3: 450 | T3: 350 | U3: 800 | V3: 117 | W3: 110 | X3: 800 | Y3: 30000 | Z3: 20000 | AA3: 30 | AC3: 2500 | AD3: 45 | AE3: 55 | AF3: 500-600 | AG3: Mak_473 draft report | AH3: Needs primary source | AI3: Needs cross-check | AJ3: Low | AK3: Payload and useful load separated later; 350+ payload but 800 useful load in draft | AL3: =R3+S3+T3 -> 1700 | AM3: =AL3-Q3 -> 0 | AN3: =AM3/Q3 -> 0 | AO3: =IF(ABS(AN3)<0.05,"OK","CHECK") -> OK | AP3: =Q3-R3-S3-T3 -> 0 | AQ3: Weight breakdown closes; still verify payload vs useful load definition. | AR3: =IF(AO3="OK","PROVISIONAL USE","SOURCE CORRECTION REQUIRED") -> PROVISIONAL USE | AS3: =IF(ABS(AN3)<0.05,"LOW",IF(ABS(AN3)<0.15,"MEDIUM","HIGH")) -> LOW | AT3: Can be used provisionally; verify whether 800 kg is useful load and 350+ kg is payload.
A4: IAI Heron | B4: Israel Aerospace Industries | C4: Israel | D4: MALE UAV | E4: Strategic intelligence and surveillance | F4: Piston Engine | G4: Not specified in draft | H4: 115 | I4: Variable Pitch | J4: 46189 | K4: 53297 | L4: 22.13 | M4: 46150 | N4: 46174 | O4: 3015 | P4: 1218 | Q4: 1270 | R4: 600 | S4: 400 | T4: 470 | U4: 670 | V4: 140 | W4: 80 | X4: 490 | Y4: 35000 | Z4: 25000-30000 | AA4: 45 | AC4: 1000 | AD4: 45 | AE4: 50 | AF4: 350-450 | AG4: Mak_473 draft report | AH4: Needs primary source | AI4: Needs cross-check | AJ4: Low | AK4: Operational range written as >1000 km; radius/range needs clarification | AL4: =R4+S4+T4 -> 1470 | AM4: =AL4-Q4 -> 200 | AN4: =AM4/Q4 -> 0.15748031 | AO4: =IF(ABS(AN4)<0.05,"OK","CHECK") -> CHECK | AP4: =Q4-R4-S4-T4 -> -200 | AQ4: Fuel + payload + empty exceeds MTOW; range/payload/fuel definition needs correction. | AR4: =IF(AO4="OK","PROVISIONAL USE","SOURCE CORRECTION REQUIRED") -> SOURCE CORRECTION REQUIRED | AS4: =IF(ABS(AN4)<0.05,"LOW",IF(ABS(AN4)<0.15,"MEDIUM","HIGH")) -> HIGH | AT4: Do not use weight breakdown before correction; fuel, payload and empty weight exceed MTOW.
A5: MQ-1 Predator | B5: General Atomics | C5: USA | D5: MALE UAV | E5: Reconnaissance and surveillance | F5: Piston Engine | G5: Not specified in draft | H5: 115 | I5: Variable Pitch | J5: 46248 | K5: 46153 | L5: 46131 | M5: 44774 | N5: 46024 | O5: 22678 | P5: 52963 | Q5: 1020 | R5: 512 | S5: 302 | T5: 204 | U5: 508 | V5: 117 | W5: 70 | X5: 500 | Y5: 25000 | Z5: 15000-20000 | AA5: 24 | AC5: 1200 | AD5: 45 | AE5: 54 | AF5: 500 | AG5: Mak_473 draft report | AH5: Needs primary source | AI5: Needs cross-check | AJ5: Low | AK5: Range/radius definition needs clarification | AL5: =R5+S5+T5 -> 1018 | AM5: =AL5-Q5 -> -2 | AN5: =AM5/Q5 -> -0.0019607843 | AO5: =IF(ABS(AN5)<0.05,"OK","CHECK") -> OK | AP5: =Q5-R5-S5-T5 -> 2 | AQ5: Weight breakdown closes within rounding error. | AR5: =IF(AO5="OK","PROVISIONAL USE","SOURCE CORRECTION REQUIRED") -> PROVISIONAL USE | AS5: =IF(ABS(AN5)<0.05,"LOW",IF(ABS(AN5)<0.15,"MEDIUM","HIGH")) -> LOW | AT5: Can be used provisionally; weight breakdown closes within rounding error.
A6: MQ-9 Reaper | B6: General Atomics | C6: USA | D6: MALE UAV | E6: Persistent strike and reconnaissance | F6: Turboprop | G6: Not specified in draft | H6: 900 | I6: Variable Pitch | J6: 20 | K6: 20 | L6: 20 | M6: 11 | N6: 46237 | O6: 5378 | P6: 3105 | Q6: 4763 | R6: 2223 | S6: 1724 | T6: 386 | U6: 2540 | V6: 260 | W6: 170 | X6: 1800 | Y6: 50000 | Z6: 25000-30000 | AA6: 27 | AC6: 1800 | AD6: 65 | AE6: 75 | AF6: 1066 | AG6: Mak_473 draft report | AH6: Needs primary source | AI6: Needs cross-check | AJ6: Low | AK6: High-power reference; useful load and payload must be separated | AL6: =R6+S6+T6 -> 4333 | AM6: =AL6-Q6 -> -430 | AN6: =AM6/Q6 -> -0.090279236 | AO6: =IF(ABS(AN6)<0.05,"OK","CHECK") -> CHECK | AP6: =Q6-R6-S6-T6 -> 430 | AQ6: MTOW exceeds empty + fuel + payload by 430 kg; likely other useful load or internal stores not listed. | AR6: =IF(AO6="OK","PROVISIONAL USE","SOURCE CORRECTION REQUIRED") -> SOURCE CORRECTION REQUIRED | AS6: =IF(ABS(AN6)<0.05,"LOW",IF(ABS(AN6)<0.15,"MEDIUM","HIGH")) -> MEDIUM | AT6: Can be used for performance trend; weight breakdown needs explanation for missing other useful load.

Sheet 05_Assumptions
A1: Category | B1: Parameter | C1: Symbol | D1: Value | E1: Unit | F1: Use in Calculation | G1: Source / Reason | H1: Confidence | I1: Notes
A2: Aerodynamics | B2: Aspect Ratio | C2: AR | D2: 20 | E2: - | F2: L/D and wing geometry | G2: Selected from MALE UAV competitor trend and high endurance requirement | H2: Medium | I2: Can be updated after final geometry
A3: Aerodynamics | B3: Oswald Efficiency Factor | C3: e | D3: 0.8 | E3: - | F3: Induced drag factor K | G3: Typical conceptual design assumption | H3: Medium | I3: Used in K=1/(pi*e*AR)
A4: Aerodynamics | B4: Zero-lift Drag Coefficient | C4: CD0 | D4: 0.025 | E4: - | F4: L/D and drag polar | G4: Clean high aspect ratio UAV assumption | H4: Medium | I4: Needs sensitivity check
A5: Aerodynamics | B5: Composite Empty Weight Correction | C5: Composite factor | D5: 0.95 | E5: - | F5: Empty weight ratio correction | G5: Initial weight estimation slide says composite aircraft may use 0.95 factor | H5: Medium | I5: Use only if assuming composite structure
A6: Propulsion | B6: Propeller Efficiency - Cruise | C6: eta_p_cruise | D6: 0.8 | E6: - | F6: Range and cruise power | G6: Typical propeller-driven conceptual assumption | H6: Medium | I6: Can be 0.75-0.85 in sensitivity
A7: Propulsion | B7: Propeller Efficiency - Climb | C7: eta_p_climb | D7: 0.75 | E7: - | F7: ROC and ceiling power | G7: Propeller efficiency lower during climb | H7: Medium | I7: Used in constraint analysis
A8: Propulsion | B8: SFC Cruise | C8: cbhp_cruise | D8: 0.4 | E8: lb/hp/hr | F8: Range sizing | G8: Initial estimate for piston/prop UAV cruise | H8: Medium | I8: Will be converted into C
A9: Propulsion | B9: SFC Loiter | C9: cbhp_loiter | D9: 0.5 | E9: lb/hp/hr | F9: Endurance sizing | G9: Initial estimate for endurance/loiter | H9: Medium | I9: Will be converted into C
A10: Lift | B10: Clean Maximum Lift Coefficient | C10: CLmax_clean | D10: 1.4 | E10: - | F10: Clean stall speed | G10: Initial clean wing assumption | H10: Medium | I10: Can vary 1.2-1.6
A11: Lift | B11: Landing Maximum Lift Coefficient | C11: CLmax_landing | D11: 2 | E11: - | F11: Landing stall speed | G11: Assuming flap/high-lift configuration | H11: Medium | I11: Can vary 1.8-2.2
A12: Mission | B12: Warm-up and Takeoff Fraction | C12: W_takeoff_fraction | D12: 0.975 | E12: - | F12: Mission fuel fraction | G12: Typical conceptual mission fraction | H12: Medium | I12: Range 0.97-0.99
A13: Mission | B13: Climb Fraction | C13: W_climb_fraction | D13: 0.98 | E13: - | F13: Mission fuel fraction | G13: Typical conceptual mission fraction | H13: Medium | I13: Can be updated using Mach-based climb formula
... A18: Weight | B18: Crew Weight | C18: Wc | D18: 0 | E18: kg | F18: Gross weight estimation | G18: UAV has no onboard crew | H18: High | I18: Ground operator is not onboard crew

Sheet 06_LD_and_Speeds
A1: Parameter | B1: Symbol | C1: Value | D1: Unit | E1: Notes
A2: Aspect Ratio | B2: AR | C2: 20 | D2: - | E2: From assumptions
A3: Oswald Efficiency | B3: e | C3: 0.8 | D3: - | E3: From assumptions
A4: Zero-lift Drag Coefficient | B4: CD0 | C4: 0.025 | D4: - | E4: From assumptions
A5: Induced Drag Factor | B5: K | C5: =1/(3.14159265*C3*C2) -> 0.019894368 | D5: - | E5: K = 1/(pi*e*AR)
A6: Maximum Lift-to-Drag Ratio | B6: LDmax | C6: =1/(2*(C4*C5)^0.5) -> 22.419965 | D6: - | E6: LDmax = 1/(2*sqrt(CD0*K))
A7: Range Lift-to-Drag Ratio | B7: LD_range | C7: =C6 -> 22.419965 | D7: - | E7: Use LDmax for range sizing
A8: Endurance Lift-to-Drag Ratio | B8: LD_endurance | C8: =0.866*C6 -> 19.41569 | D8: - | E8: Use 0.866*LDmax for prop endurance
A9: Sea Level Density | B9: rho0 | C9: 1.225 | D9: kg/m3 | E9: From atmosphere sheet
A10: Cruise Density | B10: rho_cruise | C10: 0.69798158 | D10: kg/m3 | E10: From 18000 ft atmosphere result
A11: Cruise Density Ratio | B11: sigma_cruise | C11: =C10/C9 -> 0.56978088 | D11: - | E11: rho_cruise/rho0
A12: RFP Cruise Speed CAS | B12: VC_CAS | C12: 70 | D12: kt | E12: Assume RFP cruise as Carson speed in CAS
A13: RFP Cruise Speed CAS | B13: VC_CAS | C13: =C12*0.514444 -> 36.01108 | D13: m/s | E13: kt to m/s
A14: RFP Cruise Speed TAS | B14: VC_TAS | C14: =C13/(C11^0.5) -> 47.707011 | D14: m/s | E14: CAS/sqrt(sigma)
A15: RFP Cruise Speed TAS | B15: VC_TAS | C15: =C14/0.514444 -> 92.735091 | D15: TAS in knots
A16: Best Range Speed CAS | B16: VR_CAS | C16: =C12/(3^(1/4)) -> 53.188498 | D16: kt | E16: VC/(3^(1/4))
A17: Best Endurance Speed CAS | B17: VE_CAS | C17: =C16/(3^(1/4)) -> 40.414519 | D17: kt | E17: VR/(3^(1/4))
A18: Best Range Speed TAS | B18: VR_TAS | C18: =C16*0.514444/(C11^0.5) -> 36.24949 | D18: m/s | E18: Convert VR_CAS to TAS
A19: Best Endurance Speed TAS | B19: VE_TAS | C19: =C17*0.514444/(C11^0.5) -> 27.543656 | D19: m/s | E19: Convert VE_CAS to TAS
A20: Best Range Speed TAS | B20: VR_TAS | C20: =C18/0.514444 -> 70.463431 | D20: TAS in knots
A21: Best Endurance Speed TAS | B21: VE_TAS | C21: =C19/0.514444 -> 53.54063 | D21: TAS in knots

Sheet 07_Mission_Fractions
A1: Parameter | B1: Symbol | C1: Value | D1: Unit | E1: Notes
A2: Propeller efficiency | B2: eta_p | C2: 0.8 | D2: - | E2: Used for range and endurance
A3: Gravity | B3: g | C3: 9.80665 | D3: m/s2 | E3: Standard gravity
A4: Cruise SFC | B4: cbhp_cruise | C4: 0.4 | D4: lb/hp/hr | E4: Used for range sizing
A5: Loiter SFC | B5: cbhp_loiter | C5: 0.5 | D5: lb/hp/hr | E5: Used for endurance sizing
A6: SFC conversion factor | B6: conv_SFC | C6: =0.45359237/(745.7*3600) -> 1.6896591e-07 | D6: kg/W/s | E6: Converts lb/hp/hr to kg/W/s
A7: Cruise SFC SI | B7: c_cruise_SI | C7: =C4*C6 -> 6.7586365e-08 | D7: kg/W/s | E7: Cruise SFC in SI
A8: Loiter SFC SI | B8: c_loiter_SI | C8: =C5*C6 -> 8.4482956e-08 | D8: kg/W/s | E8: Loiter SFC in SI
A9: Range L/D | B9: LD_range | C9: ='06_LD_and_Speeds'!C7 -> 22.419965 | D9: - | E9: Range uses LDmax
A10: Endurance L/D | B10: LD_endurance | C10: ='06_LD_and_Speeds'!C8 -> 19.41569 | D10: - | E10: Endurance uses 0.866 LDmax
A11: Cruise TAS | B11: V_cruise_TAS | C11: ='06_LD_and_Speeds'!C14 -> 47.707011 | D11: m/s | E11: 70 KCAS converted to TAS at 18000 ft
A12: Best range TAS | B12: V_range_TAS | C12: ='06_LD_and_Speeds'!C18 -> 36.24949 | D12: m/s | E12: Best range speed
A13: Endurance TAS selected | B13: V_endurance_TAS | C13: ='06_LD_and_Speeds'!C14 -> 47.707011 | D13: m/s | E13: Conservative baseline: endurance at RFP cruise speed
A14: Best endurance TAS theoretical | B14: V_endurance_best | C14: ='06_LD_and_Speeds'!C19 -> 27.543656 | D14: m/s | E14: Theoretical best endurance speed
A15: Endurance time | B15: E | C15: 24 | D15: h | E15: RFP endurance requirement
A16: Endurance time | B16: E | C16: =C15*3600 -> 86400 | D16: s | E16: Converted endurance time
A17: Total mission cruise range | B17: R | C17: 4000000 | D17: m | E17: 2000 km outbound + 2000 km inbound
A18: Takeoff fraction | B18: W1/W0 | C18: 0.975 | D18: - | E18: Warm-up and takeoff
A19: Climb fraction | B19: W2/W1 | C19: 0.98 | D19: - | E19: Climb to cruise altitude
A20: Descent fraction | B20: W5/W4 | C20: 0.99 | D20: - | E20: Descent
A21: Landing fraction | B21: W6/W5 | C21: 0.995 | D21: - | E21: Landing and taxi back
A22: Trapped fuel factor | C22: 1.05 | E22: 5 percent trapped/unusable fuel allowance
A23: Result | B23: Symbol | C23: Value | D23: Unit | E23: Formula / Meaning
A24: Endurance main weight fraction | B24: W_after/W_before | C24: =2.718281828^(-(C16*$C$3*$C$8*$C$13)/($C$2*$C$10)) -> 0.8026325 | D24: mission fraction | E24: From Breguet endurance
A25: Range main weight fraction | B25: W_after/W_before | C25: =2.718281828^(-($C$17*$C$3*$C$7)/($C$2*$C$9)) -> 0.86259176 | D25: mission fraction | E25: From Breguet range
A26: Range check from endurance sizing | B26: R_check | C26: =($C$2*$C$9/($C$3*$C$7))*LN(1/C24)/1000 -> 5949.6042 | D26: km | E26: Range obtained using endurance fuel fraction
A27: Endurance check from range sizing | B27: E_check | C27: =($C$2*$C$10/($C$3*$C$8*$C$13))*LN(1/C25)/3600 -> 16.135527 | D27: h | E27: Endurance obtained using range fuel fraction
A28: Total endurance mission fraction | B28: W_final/W0 | C28: =$C$18*$C$19*C24*$C$20*$C$21 -> 0.75544997 | D28: - | E28: Takeoff*climb*endurance*descent*landing
A29: Total range mission fraction | B29: W_final/W0 | C29: =$C$18*$C$19*C25*$C$20*$C$21 -> 0.81188454 | D29: - | E29: Takeoff*climb*range*descent*landing
A30: Fuel fraction from endurance sizing | B30: Wf/W0_E | C30: =$C$22*(1-C28) -> 0.25677753 | D30: - | E30: Includes trapped fuel
A31: Fuel fraction from range sizing | B31: Wf/W0_R | C31: =$C$22*(1-C29) -> 0.19752124 | D31: - | E31: Includes trapped fuel
A32: Selected fuel fraction | B32: Wf/W0_selected | C32: =MAX(C30:C31) -> 0.25677753 | D32: - | E32: Maximum of endurance and range fuel fractions

Sheet 08_Weight_Estimation
A1: Parameter | B1: Symbol | C1: Value | D1: Unit | E1: Notes
A2: Payload weight | B2: Wp | C2: 150 | D2: kg | E2: RFP payload
A3: Crew weight | B3: Wc | C3: 0 | D3: kg | E3: UAV has no onboard crew
A4: Selected fuel fraction | B4: Wf/W0 | C4: ='07_Mission_Fractions'!C32 -> 0.25677753 | D4: - | E4: From mission fractions sheet
A5: Raymer metric coefficient | B5: A | C5: 2.39 | D5: - | E5: UAV high-altitude metric coefficient
A6: Raymer exponent | B6: C | C6: -0.18 | D6: - | E6: UAV high-altitude exponent
A7: Variable sweep correction | B7: Kvs | C7: 1 | D7: - | E7: Fixed sweep aircraft, no variable sweep
A10: W0 guess kg | B10: We/W0 historical | C10: We kg | D10: Fuel fraction | E10: Fuel kg | F10: W0 calculated kg | G10: Difference kg | H10: Notes
A11: 1200 | B11: =$C$7*$C$5*(A11^$C$6) -> 0.66702986 | C11: =A11*B11 -> 800.43583 | D11: =$C$4 -> 0.25677753 | E11: =A11*D11 -> 308.13304 | F11: =($C$2+$C$3)/(1-D11-B11) -> 1968.695 | G11: =F11-A11 -> 768.69495
A12: 1400 | B12: =$C$7*$C$5*(A12^$C$6) -> 0.64877612 | C12: =A12*B12 -> 908.28656 | D12: =$C$4 -> 0.25677753 | E12: =A12*D12 -> 359.48854 | F12: =($C$2+$C$3)/(1-D12-B12) -> 1588.2032 | G12: =F12-A12 -> 188.20324
A13: 1500 | B13: =$C$7*$C$5*(A13^$C$6) -> 0.64076897 | C13: =A13*B13 -> 961.15346 | D13: =$C$4 -> 0.25677753 | E13: =A13*D13 -> 385.1663 | F13: =($C$2+$C$3)/(1-D13-B13) -> 1464.0789 | G13: =F13-A13 -> -35.921104
A14: 1480 | B14: =$C$7*$C$5*(A14^$C$6) -> 0.64231903 | C14: =A14*B14 -> 950.63217 | D14: =$C$4 -> 0.25677753 | E14: =A14*D14 -> 380.03075 | F14: =($C$2+$C$3)/(1-D14-B14) -> 1486.5698 | G14: =F14-A14 -> 6.5698324
A15: 1483 | B15: =$C$7*$C$5*(A15^$C$6) -> 0.64208495 | C15: =A15*B15 -> 952.21199 | D15: =$C$4 -> 0.25677753 | E15: =A15*D15 -> 380.80108 | F15: =($C$2+$C$3)/(1-D15-B15) -> 1483.1292 | G15: =F15-A15 -> 0.12921059
A16: 1483.1 | B16: =$C$7*$C$5*(A16^$C$6) -> 0.64207716 | C16: =A16*B16 -> 952.26464 | D16: =$C$4 -> 0.25677753 | E16: =A16*D16 -> 380.82676 | F16: =($C$2+$C$3)/(1-D16-B16) -> 1483.0149 | G16: =F16-A16 -> -0.08506141
A17: 1483.06 | B17: =$C$7*$C$5*(A17^$C$6) -> 0.64208028 | C17: =A17*B17 -> 952.24358 | D17: =$C$4 -> 0.25677753 | E17: =A17*D17 -> 380.81649 | F17: =($C$2+$C$3)/(1-D17-B17) -> 1483.0606 | G17: =F17-A17 -> 0.00064418536
A18: 1483.06 | B18: =$C$7*$C$5*(A18^$C$6) -> 0.64208028 | C18: =A18*B18 -> 952.24358 | D18: =$C$4 -> 0.25677753 | E18: =A18*D18 -> 380.81649 | F18: =($C$2+$C$3)/(1-D18-B18) -> 1483.0606 | G18: =F18-A18 -> 0.00064418536
A22: Selected Historical Weight Results
A23: Parameter | B23: Symbol | C23: Value | D23: Unit
A24: Selected gross takeoff weight | B24: W0_selected | C24: =F17 -> 1483.0606 | D24: kg
A25: Selected empty weight ratio | B25: We/W0_selected | C25: =B17 -> 0.64208028 | D25: -
A26: Selected empty weight | B26: We_selected | C26: =C17 -> 952.24358 | D26: kg
A27: Selected fuel fraction | B27: Wf/W0_selected | C27: =D17 -> 0.25677753 | D27: -
A28: Selected fuel weight | B28: Wf_selected | C28: =E17 -> 380.81649 | D28: kg
A29: Selected payload | B29: Wp_selected | C29: =$C$2 -> 150 | D29: kg
A30: Weight check | B30: W0_check | C30: =C25+C27+C26 -> 953.14244 | D30: kg
A31: Weight difference | B31: Check error | C31: =F17-A17 -> 0.00064418536 | D31: kg

Sheet 09_Mission_Profiles
A1: Endurance Mission Profile
A2: Segment | B2: Fuel Fraction | C2: Distance / Time | D2: Speed | E2: Altitude | F2: Notes
A3: Taxi & Takeoff | B3: W1/W0 = 0,975 | C3: No range credit | D3: 50 KCAS reference | E3: Sea Level | F3: Warm-up, taxi and takeoff; empirical fraction
A4: Climb | B4: W2/W1 = 0,98 | C4: No range credit | D4: Climb speed / ROC check later | E4: 0–18,000 ft | F4: Climb distance is not credited to range
A5: Endurance / Loiter | B5: ='07_Mission_Fractions'!C24 -> 0.8026325 | C5: 24 h | D5: 70 KCAS reference | E5: 18,000 ft | F5: Main endurance sizing segment; Breguet endurance result
A6: Descent | B6: W4/W3 = 0,99 | C6: No range credit | D6: Idle / descent | E6: 18,000 ft to Sea Level | F6: Low-power descent
A7: Landing | B7: W5/W4 = 0,995 | C7: No range credit | D7: 40 KCAS reference | E7: Sea Level | F7: Landing configuration
A10: Radius Mission Profile
A11: Segment | B11: Fuel Fraction | C11: Distance / Time | D11: Speed | E11: Altitude | F11: Notes
A12: Taxi & Takeoff | B12: W1/W0 = 0,975 | C12: No range credit | D12: 50 KCAS reference | E12: Sea Level | F12: Warm-up, taxi and takeoff; empirical fraction
A13: Climb | B13: W2/W1 = 0,98 | C13: No range credit | D13: Climb speed / ROC check later | E13: 0–18,000 ft | F13: Climb distance is not credited to radius/range
A14: Cruise Out | B14: Range segment fraction | C14: 2000 km | D14: 70 KCAS reference | E14: 18,000 ft | F14: Outbound leg to mission area
A15: Target / Loiter | B15: Operational requirement / optional | C15: As required | D15: Endurance or surveillance speed | E15: 18,000 ft | F15: Mission-area surveillance segment
A16: Cruise Back | B16: Range segment fraction | C16: 2000 km | D16: 70 KCAS reference | E16: 18,000 ft | F16: Return leg to base
A17: Descent | B17: W6/W5 = 0,99 | C17: No range credit | D17: Idle / descent | E17: 18,000 ft to Sea Level | F17: Low-power descent
A18: Landing | B18: W7/W6 = 0,995 | C18: No range credit | D18: 40 KCAS reference | E18: Sea Level | F18: Landing configuration

Sheet 10_Payload_Trade
A1: Payload kg | B1: W0 kg | C1: We/W0 | D1: Wf/W0 | E1: We kg | F1: Wf kg
A2: 100kg | B2: 1245 | C2: =2.39*(B2^-0.18) -> 0.66262439 | D2: ='07_Mission_Fractions'!C32 -> 0.25677753 | E2: =B2*C2 -> 824.96737 | F2: =B2*D2 -> 319.68803
A3: 110kg | B3: 1293 | C3: =2.39*(B3^-0.18) -> 0.65812769 | D3: ='07_Mission_Fractions'!C32 -> 0.25677753 | E3: =B3*C3 -> 850.95911 | F3: =B3*D3 -> 332.01335
A4: 120kg | B4: 1341 | C4: =2.39*(B4^-0.18) -> 0.65382379 | D4: ='07_Mission_Fractions'!C32 -> 0.25677753 | E4: =B4*C4 -> 876.77771 | F4: =B4*D4 -> 344.33867
A5: 130kg | B5: 1389 | C5: =2.39*(B5^-0.18) -> 0.64969795 | D5: ='07_Mission_Fractions'!C32 -> 0.25677753 | E5: =B5*C5 -> 902.43045 | F5: =B5*D5 -> 356.66399
A6: 140kg | B6: 1436 | C6: =2.39*(B6^-0.18) -> 0.64581794 | D6: ='07_Mission_Fractions'!C32 -> 0.25677753 | E6: =B6*C6 -> 927.39455 | F6: =B6*D6 -> 368.73254
A7: 150kg | B7: 1483 | C7: =2.39*(B7^-0.18) -> 0.64208495 | D7: ='07_Mission_Fractions'!C32 -> 0.25677753 | E7: =B7*C7 -> 952.21199 | F7: =B7*D7 -> 380.80108
A8: 160kg | B8: 1528 | C8: =2.39*(B8^-0.18) -> 0.63863938 | D8: ='07_Mission_Fractions'!C32 -> 0.25677753 | E8: =B8*C8 -> 975.84098 | F8: =B8*D8 -> 392.35607
A9: 170kg | B9: 1574 | C9: =2.39*(B9^-0.18) -> 0.63523885 | D9: ='07_Mission_Fractions'!C32 -> 0.25677753 | E9: =B9*C9 -> 999.86595 | F9: =B9*D9 -> 404.16784
A10: 180kg | B10: 1618 | C10: =2.39*(B10^-0.18) -> 0.63209415 | D10: ='07_Mission_Fractions'!C32 -> 0.25677753 | E10: =B10*C10 -> 1022.7283 | F10: =B10*D10 -> 415.46605
A11: 190kg | B11: 1663 | C11: =2.39*(B11^-0.18) -> 0.62898067 | D11: ='07_Mission_Fractions'!C32 -> 0.25677753 | E11: =B11*C11 -> 1045.9948 | F11: =B11*D11 -> 427.02104
A12: 200kg | B12: 1706 | C12: =2.39*(B12^-0.18) -> 0.62609708 | D12: ='07_Mission_Fractions'!C32 -> 0.25677753 | E12: =B12*C12 -> 1068.1216 | F12: =B12*D12 -> 438.06247
A94: W0 guess kg | B94: We/W0 historical | C94: We kg | D94: Fuel fraction | E94: Fuel kg | F94: W0 calculated kg | G94: Difference kg
A95: 800 | B95: =$C$7*$C$5*(A95^$C$6) -> 31.273146 | C95: =A95*B95 -> 25018.517 | D95: =$C$4 -> 0.65382379 | E95: =A95*D95 -> 523.05903 | F95: =($C$2+$C$3)/(1-D95-B95) -> -0.042705512 | G95: =F95-A95 -> -800.04271
A96: 1100 | B96: =$C$7*$C$5*(A96^$C$6) -> 38.414036 | C96: =A96*B96 -> 42255.439 | D96: =$C$4 -> 0.65382379 | E96: =A96*D96 -> 719.20617 | F96: =($C$2+$C$3)/(1-D96-B96) -> -0.034694677 | G96: =F96-A96 -> -1100.0347
A97: 1250 | B97: =$C$7*$C$5*(A97^$C$6) -> 41.719973 | C97: =A97*B97 -> 52149.966 | D97: =$C$4 -> 0.65382379 | E97: =A97*D97 -> 817.27974 | F97: =($C$2+$C$3)/(1-D97-B97) -> -0.031922429 | G97: =F97-A97 -> -1250.0319
A98: 1240 | B98: =$C$7*$C$5*(A98^$C$6) -> 41.504119 | C98: =A98*B98 -> 51465.107 | D98: =$C$4 -> 0.65382379 | E98: =A98*D98 -> 810.7415 | F98: =($C$2+$C$3)/(1-D98-B98) -> -0.032089847 | G98: =F98-A98 -> -1240.0321
A99: 1245 | B99: =$C$7*$C$5*(A99^$C$6) -> 41.612123 | C99: =A99*B99 -> 51807.093 | D99: =$C$4 -> 0.65382379 | E99: =A99*D99 -> 814.01062 | F99: =($C$2+$C$3)/(1-D99-B99) -> -0.03200586 | G99: =F99-A99 -> -1245.032
A100: 1244 | B100: =$C$7*$C$5*(A100^$C$6) -> 41.590534 | C100: =A100*B100 -> 51738.625 | D100: =$C$4 -> 0.65382379 | E100: =A100*D100 -> 813.3568 | F100: =($C$2+$C$3)/(1-D100-B100) -> -0.032022612 | G100: =F100-A100 -> -1244.032
A101: 1243 | B101: =$C$7*$C$5*(A101^$C$6) -> 41.56894 | C101: =A101*B101 -> 51670.192 | D101: =$C$4 -> 0.65382379 | E101: =A101*D101 -> 812.70298 | F101: =($C$2+$C$3)/(1-D101-B101) -> -0.032039387 | G101: =F101-A101 -> -1243.032
A102: 1243.5 | B102: =$C$7*$C$5*(A102^$C$6) -> 41.579738 | C102: =A102*B102 -> 51704.404 | D102: =$C$4 -> 0.65382379 | E102: =A102*D102 -> 813.02989 | F102: =($C$2+$C$3)/(1-D102-B102) -> -0.032030997 | G102: =F102-A102 -> -1243.532
A107: Parameter | B107: Symbol | C107: Value | D107: Unit | E107: Notes
A108: Payload weight | B108: Wp | C108: 160 | D108: kg | E108: RFP payload
A109: Crew weight | B109: Wc | C109: 0 | D109: kg | E109: UAV has no onboard crew
A110: Selected fuel fraction | B110: Wf/W0 | C110: ='07_Mission_Fractions'!C138 -> 0 | D110: - | E110: From mission fractions sheet
A111: Raymer metric coefficient | B111: A | C111: 2.39 | D111: - | E111: UAV high-altitude metric coefficient
A112: Raymer exponent | B112: C | C112: -0.18 | D112: - | E112: UAV high-altitude exponent
A113: Variable sweep correction | B113: Kvs | C113: 1 | D113: - | E113: Fixed sweep aircraft, no variable sweep
A116: W0 guess kg | B116: We/W0 historical | C116: We kg | D116: Fuel fraction | E116: Fuel kg | F116: W0 calculated kg | G116: Difference kg
A117: 800 | B117: =$C$7*$C$5*(A117^$C$6) -> 31.273146 | C117: =A117*B117 -> 25018.517 | D117: =$C$4 -> 0.65382379 | E117: =A117*D117 -> 523.05903 | F117: =($C$2+$C$3)/(1-D117-B117) -> -0.042705512 | G117: =F117-A117 -> -800.04271
A118: 1100 | B118: =$C$7*$C$5*(A118^$C$6) -> 38.414036 | C118: =A118*B118 -> 42255.439 | D118: =$C$4 -> 0.65382379 | E118: =A118*D118 -> 719.20617 | F118: =($C$2+$C$3)/(1-D118-B118) -> -0.034694677 | G118: =F118-A118 -> -1100.0347
A119: 1250 | B119: =$C$7*$C$5*(A119^$C$6) -> 41.719973 | C119: =A119*B119 -> 52149.966 | D119: =$C$4 -> 0.65382379 | E119: =A119*D119 -> 817.27974 | F119: =($C$2+$C$3)/(1-D119-B119) -> -0.031922429 | G119: =F119-A119 -> -1250.0319
A120: 1240 | B120: =$C$7*$C$5*(A120^$C$6) -> 41.504119 | C120: =A120*B120 -> 51465.107 | D120: =$C$4 -> 0.65382379 | E120: =A120*D120 -> 810.7415 | F120: =($C$2+$C$3)/(1-D120-B120) -> -0.032089847 | G120: =F120-A120 -> -1240.0321
A121: 1245 | B121: =$C$7*$C$5*(A121^$C$6) -> 41.612123 | C121: =A121*B121 -> 51807.093 | D121: =$C$4 -> 0.65382379 | E121: =A121*D121 -> 814.01062 | F121: =($C$2+$C$3)/(1-D121-B121) -> -0.03200586 | G121: =F121-A121 -> -1245.032
A122: 1244 | B122: =$C$7*$C$5*(A122^$C$6) -> 41.590534 | C122: =A122*B122 -> 51738.625 | D122: =$C$4 -> 0.65382379 | E122: =A122*D122 -> 813.3568 | F122: =($C$2+$C$3)/(1-D122-B122) -> -0.032022612 | G122: =F122-A122 -> -1244.032
A123: 1243 | B123: =$C$7*$C$5*(A123^$C$6) -> 41.56894 | C123: =A123*B123 -> 51670.192 | D123: =$C$4 -> 0.65382379 | E123: =A123*D123 -> 812.70298 | F123: =($C$2+$C$3)/(1-D123-B123) -> -0.032039387 | G123: =F123-A123 -> -1243.032
A124: 1243.5 | B124: =$C$7*$C$5*(A124^$C$6) -> 41.579738 | C124: =A124*B124 -> 51704.404 | D124: =$C$4 -> 0.65382379 | E124: =A124*D124 -> 813.02989 | F124: =($C$2+$C$3)/(1-D124-B124) -> -0.032030997 | G124: =F124-A124 -> -1243.532
A129: Parameter | B129: Symbol | C129: Value | D129: Unit | E129: Notes
A130: Payload weight | B130: Wp | C130: 170 | D130: kg | E130: RFP payload
A131: Crew weight | B131: Wc | C131: 0 | D131: kg | E131: UAV has no onboard crew
...

Sheet 11_Geometry_Sizing
A1: Parameter | B1: Symbol | C1: Value | D1: Unit | E1: Notes
A2: Selected gross takeoff weight | B2: W0 | C2: ='08_Weight_Estimation'!F18 -> 1483.0606 | D2: kg | E2: From historical weight estimation
A3: Gravity | B3: g | C3: 9.80665 | D3: m/s2 | E3: Standard gravity
A4: Aircraft weight | B4: W | C4: =C2*C3 -> 14543.857 | D4: N | E4: W = W0*g
A5: Sea level density | B5: rho0 | C5: ='03_Atmosphere'!E5 -> 1.225 | D5: kg/m3 | E5: Sea level density
A6: Landing stall speed | B6: Vs_landing | C6: =40*0.514444 -> 20.57776 | D6: m/s | E6: 40 KCAS converted to m/s
A7: Clean stall speed | B7: Vs_clean | C7: =50*0.514444 -> 25.7222 | D7: m/s | E7: 50 KCAS converted to m/s
A8: CLmax landing | B8: CLmax_L | C8: ='05_Assumptions'!D11 -> 2 | D8: - | E8: Landing configuration
A9: CLmax clean | B9: CLmax_clean | C9: ='05_Assumptions'!D10 -> 1.4 | D9: - | E9: Clean configuration
A10: Aspect Ratio | B10: AR | C10: ='05_Assumptions'!D2 -> 20 | D10: - | E10: Selected AR
A12: Result | B12: Symbol | C12: Value | D12: Unit | E12: Formula / Meaning
A13: Wing area from landing stall | B13: S_landing | C13: =C4/(0.5*C5*C6^2*C8) -> 28.038017 | D13: m2 | E13: S = W/(0.5*rho*Vs^2*CLmax)
A14: Wing area from clean stall | B14: S_clean | C14: =C4/(0.5*C5*C7^2*C9) -> 25.634759 | D14: m2 | E14: S = W/(0.5*rho*Vs^2*CLmax)
A15: Selected wing area | B15: S_selected | C15: =MAX(C13:C14) -> 28.038017 | D15: m2 | E15: Larger required wing area is selected
A16: Wingspan | B16: b | C16: =(C10*C15)^0.5 -> 23.680379 | D16: m | E16: b = sqrt(AR*S)
A17: Mean aerodynamic chord | B17: c_bar | C17: =C15/C16 -> 1.1840189 | D17: m | E17: c = S/b
A18: Wing loading | B18: W/S | C18: =C2/C15 -> 52.894633 | D18: kg/m2 | E18: W0/S in kg/m2
A19: Wing loading | B19: W/S | C19: =C4/C15 -> 518.71915 | D19: N/m2 | E19: W/S in N/m2

Sheet 12_Constraint_Analysis
A1: Parameter | B1: Symbol | C1: Value | D1: Unit | E1: Notes
A2: Selected gross takeoff weight | B2: W0 | C2: ='08_Weight_Estimation'!F18 -> 1483.0606 | D2: kg | E2: From historical weight estimation
A3: Gravity | B3: g | C3: 9.80665 | D3: m/s2 | E3: Standard gravity
A4: Aircraft weight | B4: W | C4: =C2*C3 -> 14543.857 | D4: N | E4: W = W0*g
A5: Selected wing area | B5: S | C5: ='11_Geometry_Sizing'!C15 -> 28.038017 | D5: m2 | E5: From stall sizing
A6: Wing loading | B6: W/S | C6: =C4/C5 -> 518.71915 | D6: N/m2 | E6: Wing loading in force units
A7: Aspect Ratio | B7: AR | C7: ='05_Assumptions'!D2 -> 20 | D7: - | E7: Selected AR
A8: Oswald efficiency | B8: e | C8: ='05_Assumptions'!D3 -> 0.8 | D8: - | E8: Assumed
A9: CD0 | B9: CD0 | C9: ='05_Assumptions'!D4 -> 0.025 | D9: - | E9: Zero-lift drag coefficient
A10: Induced drag factor | B10: K | C10: =1/(3.14159265*C8*C7) -> 0.019894368 | D10: - | E10: K = 1/(pi*e*AR)
A11: Sea level density | B11: rho0 | C11: 1.225 | D11: kg/m3 | E11: Sea level density
A12: ROC requirement | B12: ROC | C12: =1200*0.00508 -> 6.096 | D12: m/s | E12: 1200 fpm converted to m/s
A13: Propeller efficiency climb | B13: eta_p_climb | C13: ='05_Assumptions'!D7 -> 0.75 | D13: - | E13: Climb propeller efficiency
A14: Climb speed | B14: VY | C14: ='06_LD_and_Speeds'!C19 -> 27.543656 | D14: m/s | E14: Initial estimate: best endurance TAS used as climb speed
A15: Dynamic pressure | B15: q | C15: =0.5*C11*C14^2 -> 464.67494 | D15: N/m2 | E15: q = 0.5*rho*V^2
A16: Parasite drag term | B16: T/W_parasite | C16: =C15*C9/C6 -> 0.022395305 | D16: - | E16: q*CD0/(W/S)
A17: Induced drag term | B17: T/W_induced | C17: =C10*C6/C15 -> 0.02220819 | D17: - | E17: K*(W/S)/q
A18: Climb term | B18: T/W_climb | C18: =C12/C14 -> 0.22132138 | D18: - | E18: ROC/V
A19: Required thrust loading | B19: T/W_required | C19: =C16+C17+C18 -> 0.26592488 | D19: - | E19: ROC + parasite + induced
A20: Required propulsive power loading | B20: P/W_prop | C20: =C19*C14 -> 7.3245433 | D20: m/s | E20: (P/W)=T/W*V
A21: Required shaft power loading | B21: Pshaft/W | C21: =C20/C13 -> 9.7660578 | D21: m/s | E21: Divide by propeller efficiency
A22: Required shaft power | B22: Pshaft | C22: =C21*C4 -> 142036.14 | D22: W | E22: Power required at sea level
A23: Required shaft power | B23: Pshaft_hp | C23: =C22/745.7 -> 190.47357 | D23: hp | E23: Converted to horsepower
A26: Service Ceiling Check
A27: Parameter | B27: Symbol | C27: Value | D27: Unit | E27: Notes
A28: Service ceiling altitude | B28: h_service | C28: 24000 | D28: ft | E28: RFP service ceiling requirement
A29: Service ceiling density | B29: rho_service | C29: 0.5684 | D29: kg/m3 | E29: From atmosphere sheet at 24000 ft
A30: Service ceiling density ratio | B30: sigma_service | C30: 0.464 | D30: - | E30: rho/rho0 at 24000 ft
A31: Service ceiling ROC | B31: ROC_service | C31: =100*0.00508 -> 0.508 | D31: m/s | E31: 100 fpm service ceiling definition
A32: Best endurance speed CAS | B32: VY_CAS | C32: ='06_LD_and_Speeds'!C17 -> 40.414519 | D32: kt | E32: Best endurance speed used as climb speed reference
A33: Service ceiling climb speed TAS | B33: VY_service | C33: =C32*0.514444/(C30^0.5) -> 30.522249 | D33: m/s | E33: CAS converted to TAS at 24000 ft
A34: Dynamic pressure | B34: q_service | C34: =0.5*C29*C33^2 -> 264.7629 | D34: N/m2 | E34: q = 0.5*rho*V^2
A35: Parasite drag term | B35: T/W_parasite_service | C35: =C34*$C$9/$C$6 -> 0.012760417 | D35: - | E35: q*CD0/(W/S)
A36: Induced drag term | B36: T/W_induced_service | C36: =$C$10*$C$6/C34 -> 0.038976721 | D36: - | E36: K*(W/S)/q
A37: Climb term | B37: T/W_climb_service | C37: =C31/C33 -> 0.016643597 | D37: - | E37: ROC/V
A38: Required thrust loading | B38: T/W_service | C38: =C35+C36+C37 -> 0.068380734 | D38: - | E38: Total T/W at service ceiling
A39: Required propulsive P/W | B39: P/W_service_prop | C39: =C38*C33 -> 2.0871338 | D39: m/s | E39: (T/W)*V
A40: Piston altitude correction | B40: lapse_service | C40: =1.132*C30-0.132 -> 0.393248 | D40: - | E40: Piston power lapse correction
A41: Required SL shaft P/W | B41: Pshaft_SL/W_service | C41: =C39/($C$13*C40) -> 7.076565 | D41: m/s | E41: Sea-level shaft power loading
A42: Required SL shaft power | B42: Pshaft_service | C42: =C41*$C$4 -> 102920.55 | D42: W | E42: Required sea-level shaft power
...

Sheet 13_Compliance_Matrix
A1: Requirement | B1: Target / RFP | C1: Calculated / Selected | D1: Status | E1: Notes
A2: Payload | B2: ≥150 kg | C2: 150 kg | D2: PASS | E2: RFP payload carried
A3: Landing stall speed | B3: ≤40 KCAS | C3: 40 KCAS design limit | D3: PASS | E3: Wing area sized from landing stall requirement
A4: Clean stall speed | B4: ≤50 KCAS | C4: 50 KCAS design limit | D4: PASS | E4: Clean stall speed also checked
A5: Service ceiling | B5: >24000 ft | C5: 24000 ft check PASS | D5: PASS | E5: Required power at 24000 ft is lower than installed power
A6: Cruise ceiling | B6: >18000 ft | C6: 18000 ft check PASS | D6: PASS | E6: Required power at 18000 ft is lower than installed power
A7: Cruise speed | B7: 70 KCAS | C7: 70 KCAS | D7: PASS | E7: RFP cruise speed used as reference speed
A8: Endurance | B8: >24 h | C8: 24 h sizing case | D8: PASS | E8: Endurance mission is the sizing driver
A9: Operation radius | B9: >2000 km | C9: 2000 km outbound + 2000 km inbound | D9: PASS | E9: Total cruise range used in sizing is 4000 km
A10: Max ROC at sea level | B10: >1200 fpm | C10: 1200 fpm check PASS | D10: PASS | E10: Main installed power sizing driver
A11: Takeoff distance | B11: <2000 m | D11: PASS | E11: Optional RFP item checked
A12: Installed power | B12: - | C12: 220 hp | D12: SELECTED | E12: 15 percent margin applied over maximum required power

Sheet 14_Optional Takeoff Distance 
A1: Parameter | B1: Symbol | C1: Value | D1: Unit | E1: Notes
A2: Takeoff field altitude | B2: h_TO | C2: 0 | D2: m | E2: Sea level takeoff
A3: ISA+30 temperature | B3: T_TO | C3: 318.15 | D3: K | E3: 288.15 + 30 K
A4: Sea level pressure | B4: P0 | C4: 101325 | D4: Pa | E4: Assumed sea-level pressure
A5: Gas constant | B5: R | C5: 287.05 | D5: J/kgK | E5: Air gas constant
A6: Takeoff density | B6: rho_TO | C6: =C4/(C5*C3) -> 1.1094996 | D6: kg/m3 | E6: rho = P/(R*T)
A7: Density ratio | B7: sigma_TO | C7: =C6/1.225 -> 0.90571393 | D7: - | E7: Hot-day density ratio
A8: Installed power | B8: P_installed | C8: =220*745.7 -> 164054 | D8: W | E8: Installed shaft power from constraint summary
A9: Takeoff prop efficiency | B9: eta_TO | C9: 0.5 | D9: - | E9: Average ground-roll prop efficiency
A10: Aircraft weight | B10: W | C10: ='08_Weight_Estimation'!C24*9.80665 -> 14543.857 | D10: N | E10: From selected W0
A11: Wing loading | B11: W/S | C11: =C10/'11_Geometry_Sizing'!C15 -> 518.71915 | D11: N/m2 | E11: From selected wing area
A12: Clean stall speed | B12: Vs_clean | C12: 50 | D12: KCAS | E12: RFP clean stall speed
A13: Liftoff speed | B13: V_LOF | C13: =1.1*C12*0.514444/(C7^0.5) -> 29.730709 | D13: m/s | E13: VLOF = 1.1 Vs, corrected to hot-day TAS
A14: Average ground-roll speed | B14: V_avg | C14: =C13/(2^0.5) -> 21.022786 | D14: m/s | E14: Average speed during ground roll
A15: Average dynamic pressure | B15: q_avg | C15: =0.5*C6*C14^2 -> 245.17585 | D15: N/m2 | E15: q at VLOF/sqrt(2)
A16: Takeoff lift coefficient | B16: CL_TO | C16: 0.8 | D16: - | E16: Conceptual takeoff value
A17: Takeoff drag coefficient | B17: CD_TO | C17: 0.04 | D17: - | E17: Conceptual takeoff drag value
A18: Ground friction coefficient | B18: mu | C18: 0.04 | D18: - | E18: Dry runway, brakes off
A19: Takeoff thrust loading | B19: T/W_TO | C19: =C8*C9/(C14*C10) -> 0.26827918 | D19: - | E19: T/W = eta P/(Vavg W)
A20: Parasite drag term | B20: D/W_TO | C20: =C15*C17/C11 -> 0.01890625 | D20: - | E20: q CD_TO/(W/S)
A21: Lift relief term | B21: L/W_TO | C21: =C15*C16/C11 -> 0.378125 | D21: - | E21: q CL_TO/(W/S)
A22: Ground friction term | B22: mu_term | C22: =C18*(1-C21) -> 0.024875 | D22: - | E22: mu(1-L/W)
A23: Acceleration term | B23: accel_term | C23: =C19-C20-C22 -> 0.22449793 | D23: - | E23: Available acceleration term
A24: Ground roll | B24: S_G | C24: =C13^2/(2*9.80665*C23) -> 200.7463 | D24: m | E24: Ground roll distance
A25: Rotation distance | B25: S_R | C25: =3*C13 -> 89.192128 | D25: m | E25: 3 seconds at VLOF
A26: Obstacle height | B26: h_obs | C26: 15.24 | D26: m | E26: 50 ft obstacle
A27: Climb angle | B27: gamma_TO | C27: 10 | D27: deg | E27: Conceptual airborne climb angle
A28: Airborne distance | B28: S_A | C28: =C26/TAN(RADIANS(C27)) -> 86.430335 | D28: m | E28: Distance to obstacle
A29: Total takeoff distance | B29: S_TO | C29: =C24+C25+C28 -> 376.36876 | D29: m | E29: Ground roll + rotation + airborne
A30: RFP takeoff limit | B30: S_TO_limit | C30: 2000 | D30: m | E30: Optional RFP limit | H30: S
A31: Status | B31: Takeoff status | C31: =IF(C29<=C30,"PASS","FAIL") -> PASS | D31: - | E31: Optional takeoff check

Sheet 15_
A1: Final Design Summary
A2: Parameter | B2: Symbol | C2: Value | D2: Unit
A3: Gross takeoff weight | B3: W0 | C3: 1483.06 | D3: kg
A4: Empty weight | B4: We | C4: 952.24 | D4: kg
A5: Fuel weight | B5: Wf | C5: 380.82 | D5: kg
A6: Payload weight | B6: Wp | C6: 150 | D6: kg
A7: Fuel fraction | B7: Wf/W0 | C7: 0.25678 | D7: -
A8: Empty weight ratio | B8: We/W0 | C8: 0.64208 | D8: -
A9: Aspect ratio | B9: AR | C9: 20 | D9: -
A10: Zero-lift drag coefficient | B10: CD0 | C10: 0.025 | D10: -
A11: Oswald efficiency | B11: e | C11: 0.8 | D11: -
A12: Induced drag factor | B12: K | C12: 0.01989 | D12: -
A13: L/D max | B13: (L/D)max | C13: 22.42 | D13: -
A14: Endurance L/D | B14: (L/D)E | C14: 19.42 | D14: -
... A27: Selected installed power | B27: P_selected | C27: 220 | D27: hp
A28: Service ceiling check | B28: - | C28: PASS | D28: -
A29: Cruise ceiling check | B29: - | C29: PASS | D29: -
A30: Takeoff distance check | B30: - | C30: PASS | D30: -
A31: Endurance requirement | B31: - | C31: 24 | D31: h
A32: Operational radius requirement | B32: - | C32: 2000 | D32: km
A33: Total cruise range used in sizing | B33: - | C33: 4000 | D33: km

Sheet RAW Constrait
A1: W/S (N/m^2) | B1: SL RoC(W/N) | C1: Serivce Celling | D1: 18k Cruise | E1: Stall limit
A2: 100 | B2: =(27.54/0.75)*((464.67*0.025)/A2+(0.01989/464.67)*A2)+(6.096/0.75) -> 12.550849 | C2: =(30.52/0.75) * ((264.76 * 0.025)/A2 + (0.01989/264.76)*A2) + (0.508/0.75) -> 3.6765323 | D2: =(47.7/0.8) * ((794.13 * 0.025)/A2 + (0.01989/794.13)*A2) -> 11.986839 | E2: 518.7
A3: =A2+10 -> 110 | B3: =(27.54/0.75)*((464.67*0.025)/A3+(0.01989/464.67)*A3)+(6.096/0.75) -> 12.178779 | C3: =(30.52/0.75) * ((264.76 * 0.025)/A3 + (0.01989/264.76)*A3) + (0.508/0.75) -> 3.4622401 | D3: =(47.7/0.8) * ((794.13 * 0.025)/A3 + (0.01989/794.13)*A3) -> 10.925636 | H3: Optimum Point = 518.7 , 9.77
A4: =A3+10 -> 120 | B4: =(27.54/0.75)*((464.67*0.025)/A4+(0.01989/464.67)*A4)+(6.096/0.75) -> 11.87134 | C4: =(30.52/0.75) * ((264.76 * 0.025)/A4 + (0.01989/264.76)*A4) + (0.508/0.75) -> 3.2887584 | D4: =(47.7/0.8) * ((794.13 * 0.025)/A4 + (0.01989/794.13)*A4) -> 10.04379
A5: =A4+10 -> 130 | B5: =(27.54/0.75)*((464.67*0.025)/A5+(0.01989/464.67)*A5)+(6.096/0.75) -> 11.613617 | C5: =(30.52/0.75) * ((264.76 * 0.025)/A5 + (0.01989/264.76)*A5) + (0.508/0.75) -> 3.1466694 | D5: =(47.7/0.8) * ((794.13 * 0.025)/A5 + (0.01989/794.13)*A5) -> 9.2999094 | M5: K = 0.01989
A6: =A5+10 -> 140 | B6: =(27.54/0.75)*((464.67*0.025)/A6+(0.01989/464.67)*A6)+(6.096/0.75) -> 11.394957 | C6: =(30.52/0.75) * ((264.76 * 0.025)/A6 + (0.01989/264.76)*A6) + (0.508/0.75) -> 3.0292461 | D6: =(47.7/0.8) * ((794.13 * 0.025)/A6 + (0.01989/794.13)*A6) -> 8.6644312 | M6: C_{D0} = 0.025
A7: =A6+10 -> 150 | B7: =(27.54/0.75)*((464.67*0.025)/A7+(0.01989/464.67)*A7)+(6.096/0.75) -> 11.207548 | C7: =(30.52/0.75) * ((264.76 * 0.025)/A7 + (0.01989/264.76)*A7) + (0.508/0.75) -> 2.9315553 | D7: =(47.7/0.8) * ((794.13 * 0.025)/A7 + (0.01989/794.13)*A7) -> 8.1156745 | M7: $V = 27.54$
A8: =A7+10 -> 160 | B8: =(27.54/0.75)*((464.67*0.025)/A8+(0.01989/464.67)*A8)+(6.096/0.75) -> 11.04553 | C8: =(30.52/0.75) * ((264.76 * 0.025)/A8 + (0.01989/264.76)*A8) + (0.508/0.75) -> 2.8498972 | D8: =(47.7/0.8) * ((794.13 * 0.025)/A8 + (0.01989/794.13)*A8) -> 7.6373792
A9: =A8+10 -> 170 | B9: =(27.54/0.75)*((464.67*0.025)/A9+(0.01989/464.67)*A9)+(6.096/0.75) -> 10.904421 | C9: =(30.52/0.75) * ((264.76 * 0.025)/A9 + (0.01989/264.76)*A9) + (0.508/0.75) -> 2.7814425 | D9: =(47.7/0.8) * ((794.13 * 0.025)/A9 + (0.01989/794.13)*A9) -> 7.2171108
A10: =A9+10 -> 180 | B10: =(27.54/0.75)*((464.67*0.025)/A10+(0.01989/464.67)*A10)+(6.096/0.75) -> 10.780738 | C10: =(30.52/0.75) * ((264.76 * 0.025)/A10 + (0.01989/264.76)*A10) + (0.508/0.75) -> 2.7239906 | D10: =(47.7/0.8) * ((794.13 * 0.025)/A10 + (0.01989/794.13)*A10) -> 6.8451982
A11: =A10+10 -> 190 | B11: =(27.54/0.75)*((464.67*0.025)/A11+(0.01989/464.67)*A11)+(6.096/0.75) -> 10.671729 | C11: =(30.52/0.75) * ((264.76 * 0.025)/A11 + (0.01989/264.76)*A11) + (0.508/0.75) -> 2.6758043 | D11: =(47.7/0.8) * ((794.13 * 0.025)/A11 + (0.01989/794.13)*A11) -> 6.5140063
A12: =A11+10 -> 200 | B12: =(27.54/0.75)*((464.67*0.025)/A12+(0.01989/464.67)*A12)+(6.096/0.75) -> 10.575192 | C12: =(30.52/0.75) * ((264.76 * 0.025)/A12 + (0.01989/264.76)*A12) + (0.508/0.75) -> 2.6354936 | D12: =(47.7/0.8) * ((794.13 * 0.025)/A12 + (0.01989/794.13)*A12) -> 6.217427
A13: =A12+10 -> 210 | B13: =(27.54/0.75)*((464.67*0.025)/A13+(0.01989/464.67)*A13)+(6.096/0.75) -> 10.489346 | C13: =(30.52/0.75) * ((264.76 * 0.025)/A13 + (0.01989/264.76)*A13) + (0.508/0.75) -> 2.6019336 | D13: =(47.7/0.8) * ((794.13 * 0.025)/A13 + (0.01989/794.13)*A13) -> 5.9505156
A14: =A13+10 -> 220 | B14: =(27.54/0.75)*((464.67*0.025)/A14+(0.01989/464.67)*A14)+(6.096/0.75) -> 10.412734 | C14: =(30.52/0.75) * ((264.76 * 0.025)/A14 + (0.01989/264.76)*A14) + (0.508/0.75) -> 2.5742036 | D14: =(47.7/0.8) * ((794.13 * 0.025)/A14 + (0.01989/794.13)*A14) -> 5.7092265
A15: =A14+10 -> 230 | B15: =(27.54/0.75)*((464.67*0.025)/A15+(0.01989/464.67)*A15)+(6.096/0.75) -> 10.34415 | C15: =(30.52/0.75) * ((264.76 * 0.025)/A15 + (0.01989/264.76)*A15) + (0.508/0.75) -> 2.5515433 | D15: =(47.7/0.8) * ((794.13 * 0.025)/A15 + (0.01989/794.13)*A15) -> 5.4902176
A16: =A15+10 -> 240 | B16: =(27.54/0.75)*((464.67*0.025)/A16+(0.01989/464.67)*A16)+(6.096/0.75) -> 10.282591 | C16: =(30.52/0.75) * ((264.76 * 0.025)/A16 + (0.01989/264.76)*A16) + (0.508/0.75) -> 2.5333189 | D16: =(47.7/0.8) * ((794.13 * 0.025)/A16 + (0.01989/794.13)*A16) -> 5.290704
A17: =A16+10 -> 250 | B17: =(27.54/0.75)*((464.67*0.025)/A17+(0.01989/464.67)*A17)+(6.096/0.75) -> 10.227214 | C17: =(30.52/0.75) * ((264.76 * 0.025)/A17 + (0.01989/264.76)*A17) + (0.508/0.75) -> 2.518998 | D17: =(47.7/0.8) * ((794.13 * 0.025)/A17 + (0.01989/794.13)*A17) -> 5.1083462
A18: =A17+10 -> 260 | B18: =(27.54/0.75)*((464.67*0.025)/A18+(0.01989/464.67)*A18)+(6.096/0.75) -> 10.177306 | C18: =(30.52/0.75) * ((264.76 * 0.025)/A18 + (0.01989/264.76)*A18) + (0.508/0.75) -> 2.5081304 | D18: =(47.7/0.8) * ((794.13 * 0.025)/A18 + (0.01989/794.13)*A18) -> 4.9411646
A19: =A18+10 -> 270 | B19: =(27.54/0.75)*((464.67*0.025)/A19+(0.01989/464.67)*A19)+(6.096/0.75) -> 10.13226 | C19: =(30.52/0.75) * ((264.76 * 0.025)/A19 + (0.01989/264.76)*A19) + (0.508/0.75) -> 2.5003323 | D19: =(47.7/0.8) * ((794.13 * 0.025)/A19 + (0.01989/794.13)*A19) -> 4.7874731
... A74: =A73+10 -> 820 | B74: =(27.54/0.75)*((464.67*0.025)/A74+(0.01989/464.67)*A74)+(6.096/0.75) -> 9.9370665 | C74: =(30.52/0.75) * ((264.76 * 0.025)/A74 + (0.01989/264.76)*A74) + (0.508/0.75) -> 3.512607 | D74: =(47.7/0.8) * ((794.13 * 0.025)/A74 + (0.01989/794.13)*A74) -> 2.6681727

Sheet Normalization
A1: W/S (N/m^2) | B1: SL RoC(W/N) | C1: Service Ceiling | D1: 18k Cruise | E1: Stall Limit
A2: 100 | B2: =(27.54/0.75)*((464.67*0.025)/A2+(0.01989/464.67)*A2)+(6.096/0.75) -> 12.550849 | C2: =( (30.52/0.75) * ((264.76 * 0.025)/A2 + (0.01989/264.76)*A2) + (0.508/0.75) ) / 0.393248 -> 9.3491442 | D2: =( (47.7/0.8) * ((794.13 * 0.025)/A2 + (0.01989/794.13)*A2) ) / 0.512991 -> 23.366567 | E2: 518.7
A3: =A2+10 -> 110 | B3: =(27.54/0.75)*((464.67*0.025)/A3+(0.01989/464.67)*A3)+(6.096/0.75) -> 12.178779 | C3: =( (30.52/0.75) * ((264.76 * 0.025)/A3 + (0.01989/264.76)*A3) + (0.508/0.75) ) / 0.393248 -> 8.8042154 | D3: =( (47.7/0.8) * ((794.13 * 0.025)/A3 + (0.01989/794.13)*A3) ) / 0.512991 -> 21.29791 | E3: 518.7
A4: =A3+10 -> 120 | B4: =(27.54/0.75)*((464.67*0.025)/A4+(0.01989/464.67)*A4)+(6.096/0.75) -> 11.87134 | C4: =( (30.52/0.75) * ((264.76 * 0.025)/A4 + (0.01989/264.76)*A4) + (0.508/0.75) ) / 0.393248 -> 8.3630646 | D4: =( (47.7/0.8) * ((794.13 * 0.025)/A4 + (0.01989/794.13)*A4) ) / 0.512991 -> 19.578881 | E4: 518.7
A5: =A4+10 -> 130 | B5: =(27.54/0.75)*((464.67*0.025)/A5+(0.01989/464.67)*A5)+(6.096/0.75) -> 11.613617 | C5: =( (30.52/0.75) * ((264.76 * 0.025)/A5 + (0.01989/264.76)*A5) + (0.508/0.75) ) / 0.393248 -> 8.001743 | D5: =( (47.7/0.8) * ((794.13 * 0.025)/A5 + (0.01989/794.13)*A5) ) / 0.512991 -> 18.128796 | E5: 518.7
A6: =A5+10 -> 140 | B6: =(27.54/0.75)*((464.67*0.025)/A6+(0.01989/464.67)*A6)+(6.096/0.75) -> 11.394957 | C6: =( (30.52/0.75) * ((264.76 * 0.025)/A6 + (0.01989/264.76)*A6) + (0.508/0.75) ) / 0.393248 -> 7.7031443 | D6: =( (47.7/0.8) * ((794.13 * 0.025)/A6 + (0.01989/794.13)*A6) ) / 0.512991 -> 16.890026 | E6: 518.7
A7: =A6+10 -> 150 | B7: =(27.54/0.75)*((464.67*0.025)/A7+(0.01989/464.67)*A7)+(6.096/0.75) -> 11.207548 | C7: =( (30.52/0.75) * ((264.76 * 0.025)/A7 + (0.01989/264.76)*A7) + (0.508/0.75) ) / 0.393248 -> 7.454724 | D7: =( (47.7/0.8) * ((794.13 * 0.025)/A7 + (0.01989/794.13)*A7) ) / 0.512991 -> 15.820306 | E7: 518.7
A8: =A7+10 -> 160 | B8: =(27.54/0.75)*((464.67*0.025)/A8+(0.01989/464.67)*A8)+(6.096/0.75) -> 11.04553 | C8: =( (30.52/0.75) * ((264.76 * 0.025)/A8 + (0.01989/264.76)*A8) + (0.508/0.75) ) / 0.393248 -> 7.2470736 | D8: =( (47.7/0.8) * ((794.13 * 0.025)/A8 + (0.01989/794.13)*A8) ) / 0.512991 -> 14.88794 | E8: 518.7
A9: =A8+10 -> 170 | B9: =(27.54/0.75)*((464.67*0.025)/A9+(0.01989/464.67)*A9)+(6.096/0.75) -> 10.904421 | C9: =( (30.52/0.75) * ((264.76 * 0.025)/A9 + (0.01989/264.76)*A9) + (0.508/0.75) ) / 0.393248 -> 7.0729984 | D9: =( (47.7/0.8) * ((794.13 * 0.025)/A9 + (0.01989/794.13)*A9) ) / 0.512991 -> 14.068689 | E9: 518.7
A10: =A9+10 -> 180 | B10: =(27.54/0.75)*((464.67*0.025)/A10+(0.01989/464.67)*A10)+(6.096/0.75) -> 10.780738 | C10: =( (30.52/0.75) * ((264.76 * 0.025)/A10 + (0.01989/264.76)*A10) + (0.508/0.75) ) / 0.393248 -> 6.9269026 | D10: =( (47.7/0.8) * ((794.13 * 0.025)/A10 + (0.01989/794.13)*A10) ) / 0.512991 -> 13.3437 | E10: 518.7
A11: =A10+10 -> 190 | B11: =(27.54/0.75)*((464.67*0.025)/A11+(0.01989/464.67)*A11)+(6.096/0.75) -> 10.671729 | C11: =( (30.52/0.75) * ((264.76 * 0.025)/A11 + (0.01989/264.76)*A11) + (0.508/0.75) ) / 0.393248 -> 6.8043684 | D11: =( (47.7/0.8) * ((794.13 * 0.025)/A11 + (0.01989/794.13)*A11) ) / 0.512991 -> 12.698091 | E11: 518.7
A12: =A11+10 -> 200 | B12: =(27.54/0.75)*((464.67*0.025)/A12+(0.01989/464.67)*A12)+(6.096/0.75) -> 10.575192 | C12: =( (30.52/0.75) * ((264.76 * 0.025)/A12 + (0.01989/264.76)*A12) + (0.508/0.75) ) / 0.393248 -> 6.7018615 | D12: =( (47.7/0.8) * ((794.13 * 0.025)/A12 + (0.01989/794.13)*A12) ) / 0.512991 -> 12.119953 | E12: 518.7
A13: =A12+10 -> 210 | B13: =(27.54/0.75)*((464.67*0.025)/A13+(0.01989/464.67)*A13)+(6.096/0.75) -> 10.489346 | C13: =( (30.52/0.75) * ((264.76 * 0.025)/A13 + (0.01989/264.76)*A13) + (0.508/0.75) ) / 0.393248 -> 6.6165208 | D13: =( (47.7/0.8) * ((794.13 * 0.025)/A13 + (0.01989/794.13)*A13) ) / 0.512991 -> 11.599649 | E13: 518.7
A14: =A13+10 -> 220 | B14: =(27.54/0.75)*((464.67*0.025)/A14+(0.01989/464.67)*A14)+(6.096/0.75) -> 10.412734 | C14: =( (30.52/0.75) * ((264.76 * 0.025)/A14 + (0.01989/264.76)*A14) + (0.508/0.75) ) / 0.393248 -> 6.5460056 | D14: =( (47.7/0.8) * ((794.13 * 0.025)/A14 + (0.01989/794.13)*A14) ) / 0.512991 -> 11.129292 | E14: 518.7
... A74: =A73+10 -> 820 | B74: =(27.54/0.75)*((464.67*0.025)/A74+(0.01989/464.67)*A74)+(6.096/0.75) -> 9.9370665 | C74: =( (30.52/0.75) * ((264.76 * 0.025)/A74 + (0.01989/264.76)*A74) + (0.508/0.75) ) / 0.393248 -> 8.9322947 | D74: =( (47.7/0.8) * ((794.13 * 0.025)/A74 + (0.01989/794.13)*A74) ) / 0.512991 -> 5.2012076 | E74: 518.7

Sheet Weight_Norm_Constraint
A1: W/S (N/m^2) | B1: SL RoC(W/N) | C1: Serivce Celling | D1: 18k Cruise
A2: 100 | B2: =(27.54/0.75)*((464.67*0.025)/A2+(0.01989/464.67)*A2)+(6.096/0.75) -> 12.550849 | C2: =(0.9555 / 0.393248) * ( (30.52/0.75) * ((264.76 * 0.025)/(A2 * 0.9555) + (0.01989/264.76)*(A2 * 0.9555)) + (0.508/0.75) ) -> 9.2048488 | D2: =(0.9555 / 0.512991) * ( (47.7/0.8) * ((794.13 * 0.025)/(A2 * 0.9555) + (0.01989/794.13)*(A2 * 0.9555)) ) -> 23.341235
A3: =A2+10 -> 110 | B3: =(27.54/0.75)*((464.67*0.025)/A3+(0.01989/464.67)*A3)+(6.096/0.75) -> 12.178779 | C3: =(0.9555 / 0.393248) * ( (30.52/0.75) * ((264.76 * 0.025)/(A3 * 0.9555) + (0.01989/264.76)*(A3 * 0.9555)) + (0.508/0.75) ) -> 8.6531551 | D3: =(0.9555 / 0.512991) * ( (47.7/0.8) * ((794.13 * 0.025)/(A3 * 0.9555) + (0.01989/794.13)*(A3 * 0.9555)) ) -> 21.270044
A4: =A3+10 -> 120 | B4: =(27.54/0.75)*((464.67*0.025)/A4+(0.01989/464.67)*A4)+(6.096/0.75) -> 11.87134 | C4: =(0.9555 / 0.393248) * ( (30.52/0.75) * ((264.76 * 0.025)/(A4 * 0.9555) + (0.01989/264.76)*(A4 * 0.9555)) + (0.508/0.75) ) -> 8.2052395 | D4: =(0.9555 / 0.512991) * ( (47.7/0.8) * ((794.13 * 0.025)/(A4 * 0.9555) + (0.01989/794.13)*(A4 * 0.9555)) ) -> 19.548482
A5: =A4+10 -> 130 | B5: =(27.54/0.75)*((464.67*0.025)/A5+(0.01989/464.67)*A5)+(6.096/0.75) -> 11.613617 | C5: =(0.9555 / 0.393248) * ( (30.52/0.75) * ((264.76 * 0.025)/(A5 * 0.9555) + (0.01989/264.76)*(A5 * 0.9555)) + (0.508/0.75) ) -> 7.837153 | D5: =(0.9555 / 0.512991) * ( (47.7/0.8) * ((794.13 * 0.025)/(A5 * 0.9555) + (0.01989/794.13)*(A5 * 0.9555)) ) -> 18.095864
A6: =A5+10 -> 140 | B6: =(27.54/0.75)*((464.67*0.025)/A6+(0.01989/464.67)*A6)+(6.096/0.75) -> 11.394957 | C6: =(0.9555 / 0.393248) * ( (30.52/0.75) * ((264.76 * 0.025)/(A6 * 0.9555) + (0.01989/264.76)*(A6 * 0.9555)) + (0.508/0.75) ) -> 7.5317895 | D6: =(0.9555 / 0.512991) * ( (47.7/0.8) * ((794.13 * 0.025)/(A6 * 0.9555) + (0.01989/794.13)*(A6 * 0.9555)) ) -> 16.85456
A7: =A6+10 -> 150 | B7: =(27.54/0.75)*((464.67*0.025)/A7+(0.01989/464.67)*A7)+(6.096/0.75) -> 11.207548 | C7: =(0.9555 / 0.393248) * ( (30.52/0.75) * ((264.76 * 0.025)/(A7 * 0.9555) + (0.01989/264.76)*(A7 * 0.9555)) + (0.508/0.75) ) -> 7.2766044 | D7: =(0.9555 / 0.512991) * ( (47.7/0.8) * ((794.13 * 0.025)/(A7 * 0.9555) + (0.01989/794.13)*(A7 * 0.9555)) ) -> 15.782307
A8: =A7+10 -> 160 | B8: =(27.54/0.75)*((464.67*0.025)/A8+(0.01989/464.67)*A8)+(6.096/0.75) -> 11.04553 | C8: =(0.9555 / 0.393248) * ( (30.52/0.75) * ((264.76 * 0.025)/(A8 * 0.9555) + (0.01989/264.76)*(A8 * 0.9555)) + (0.508/0.75) ) -> 7.0621892 | D8: =(0.9555 / 0.512991) * ( (47.7/0.8) * ((794.13 * 0.025)/(A8 * 0.9555) + (0.01989/794.13)*(A8 * 0.9555)) ) -> 14.847408
A9: =A8+10 -> 170 | B9: =(27.54/0.75)*((464.67*0.025)/A9+(0.01989/464.67)*A9)+(6.096/0.75) -> 10.904421 | C9: =(0.9555 / 0.393248) * ( (30.52/0.75) * ((264.76 * 0.025)/(A9 * 0.9555) + (0.01989/264.76)*(A9 * 0.9555)) + (0.508/0.75) ) -> 6.8813492 | D9: =(0.9555 / 0.512991) * ( (47.7/0.8) * ((794.13 * 0.025)/(A9 * 0.9555) + (0.01989/794.13)*(A9 * 0.9555)) ) -> 14.025624
A10: =A9+10 -> 180 | B10: =(27.54/0.75)*((464.67*0.025)/A10+(0.01989/464.67)*A10)+(6.096/0.75) -> 10.780738 | C10: =(0.9555 / 0.393248) * ( (30.52/0.75) * ((264.76 * 0.025)/(A10 * 0.9555) + (0.01989/264.76)*(A10 * 0.9555)) + (0.508/0.75) ) -> 6.7284885 | D10: =(0.9555 / 0.512991) * ( (47.7/0.8) * ((794.13 * 0.025)/(A10 * 0.9555) + (0.01989/794.13)*(A10 * 0.9555)) ) -> 13.298102
A11: =A10+10 -> 190 | B11: =(27.54/0.75)*((464.67*0.025)/A11+(0.01989/464.67)*A11)+(6.096/0.75) -> 10.671729 | C11: =(0.9555 / 0.393248) * ( (30.52/0.75) * ((264.76 * 0.025)/(A11 * 0.9555) + (0.01989/264.76)*(A11 * 0.9555)) + (0.508/0.75) ) -> 6.5991894 | D11: =(0.9555 / 0.512991) * ( (47.7/0.8) * ((794.13 * 0.025)/(A11 * 0.9555) + (0.01989/794.13)*(A11 * 0.9555)) ) -> 12.649959
A12: =A11+10 -> 200 | B12: =(27.54/0.75)*((464.67*0.025)/A12+(0.01989/464.67)*A12)+(6.096/0.75) -> 10.575192 | C12: =(0.9555 / 0.393248) * ( (30.52/0.75) * ((264.76 * 0.025)/(A12 * 0.9555) + (0.01989/264.76)*(A12 * 0.9555)) + (0.508/0.75) ) -> 6.4899177 | D12: =(0.9555 / 0.512991) * ( (47.7/0.8) * ((794.13 * 0.025)/(A12 * 0.9555) + (0.01989/794.13)*(A12 * 0.9555)) ) -> 12.069288
A13: =A12+10 -> 210 | B13: =(27.54/0.75)*((464.67*0.025)/A13+(0.01989/464.67)*A13)+(6.096/0.75) -> 10.489346 | C13: =(0.9555 / 0.393248) * ( (30.52/0.75) * ((264.76 * 0.025)/(A13 * 0.9555) + (0.01989/264.76)*(A13 * 0.9555)) + (0.508/0.75) ) -> 6.3978122 | D13: =(0.9555 / 0.512991) * ( (47.7/0.8) * ((794.13 * 0.025)/(A13 * 0.9555) + (0.01989/794.13)*(A13 * 0.9555)) ) -> 11.546451
A14: =A13+10 -> 220 | B14: =(27.54/0.75)*((464.67*0.025)/A14+(0.01989/464.67)*A14)+(6.096/0.75) -> 10.412734 | C14: =(0.9555 / 0.393248) * ( (30.52/0.75) * ((264.76 * 0.025)/(A14 * 0.9555) + (0.01989/264.76)*(A14 * 0.9555)) + (0.508/0.75) ) -> 6.3205322 | D14: =(0.9555 / 0.512991) * ( (47.7/0.8) * ((794.13 * 0.025)/(A14 * 0.9555) + (0.01989/794.13)*(A14 * 0.9555)) ) -> 11.07356
... A74: =A73+10 -> 820 | B74: =(27.54/0.75)*((464.67*0.025)/A74+(0.01989/464.67)*A74)+(6.096/0.75) -> 9.9370665 | C74: =(0.9555 / 0.393248) * ( (30.52/0.75) * ((264.76 * 0.025)/(A74 * 0.9555) + (0.01989/264.76)*(A74 * 0.9555)) + (0.508/0.75) ) -> 8.3009314 | D74: =(0.9555 / 0.512991) * ( (47.7/0.8) * ((794.13 * 0.025)/(A74 * 0.9555) + (0.01989/794.13)*(A74 * 0.9555)) ) -> 4.9934804
